I'm sorry, but an uncaught exception occurred.

While running game code:
  File "game/scenes/introduction.rpy", line 198, in script
    dtective "Okay! Let's go! Time to solve the mystery!"
Exception: Sayer 'dtective' is not defined.

-- Full Traceback ------------------------------------------------------------

Full traceback:
  File "game/scenes/introduction.rpy", line 198, in script
    dtective "Okay! Let's go! Time to solve the mystery!"
  File "C:\Users\False\Desktop\renpy-7.3.5-sdk\renpy\ast.py", line 678, in execute
    who = eval_who(self.who, self.who_fast)
  File "C:\Users\False\Desktop\renpy-7.3.5-sdk\renpy\ast.py", line 576, in eval_who
    raise Exception("Sayer '%s' is not defined." % who.encode("utf-8"))
Exception: Sayer 'dtective' is not defined.

Windows-8-6.2.9200
Ren'Py 7.3.5.606
cct382_vn 1.0
Sat Nov 28 22:20:12 2020
